1. 下面会输出什么

   ```go
   package main
   
   import "fmt"
   
   func defer_all() {
      defer func() { fmt.Println("print before recovery") }()
      defer func() { recover() }()
      defer func() { fmt.Println("print after recovery") }()
      panic("panic info")
   }
   func main() {
      defer_all()
   }
   //print after recovery
   //print before recovery
   ```

   如果recover() 不是在函数内,是不能处理异常的.

2. 下面会输出什么?

   ```go
   package main
   
   import "fmt"
   
   func calc(index string, a, b int) int {
      ret := a + b
      fmt.Println(index, a, b, ret)
      return ret
   }
   func main() {
      a := 1
      b := 2
      defer calc("1", a, calc("10", a, b))
      a = 0
      defer calc("2", a, calc("20", a, b))
      b = 1
   }
   
   //10 1 2 3
   //20 0 2 2
   //2 0 2 2
   //1 1 3 4
   ```

   defer 挨着的函数会不执行, 内部的函数会执行